Workbook

Sheet Assumptions
A1: Circumpolar wave timing — inputs
A2: Blue = input. Every arrival time in this workbook is a formula off these cells. Change a blue cell and the whole book moves. Day 0 is 15 May 2031 UTC.
A4: Wave physics | B4: value | C4: unit | D4: note
A5: Deep-water wave speed | B5: 198.1 | C5: m/s | D5: sqrt(g*h) at h = 4,000 m; 713 km/h
A6: Shelf wave speed | B6: 70 | C6: m/s | D6: sqrt(g*h) at h = 500 m; inside the embayments
A7: km per degree of longitude at 65 S | B7: 47 | C7: km/deg | D7: 40,030 * cos(65) / 360
A8: T0 — Prydz Bay collapse | B8: 47983.139 | C8: GMT | D8: Fixed by lyx/ice.lyx. 2031-05-15T03:20Z.
A10: Circumpolar arrival at each shelf
A11: Shelf | B11: Branch | C11: Path (deg / km / h) | D11: Wave at embayment mouth (GMT) | E11: Mouth to front (km) | F11: Speed on that leg (m/s) | G11: In-embayment leg (h) | H11: COLLAPSE AT FRONT (GMT) | J11: The Amundsen is rung twice.
A12: Prydz Bay / Amery | B12: — | C12: source of the wave | D12: — | E12: — | F12: — | G12: — | H12: =$B$8 -> 47983.139 | J12: The eastward and westward branches converge on the Amundsen from opposite directions, ~15:00Z and ~15:15Z. Cell D15 carries the first.
A13: Ross | B13: eastward | C13: 107 deg, ~5,000 km, ~7.0 h | D13: 47983.431 | E13: 900 | F13: 110 | G13: =IF(E13=0,0,E13*1000/F13/3600) -> 2.2727273 | H13: =D13+G13/24 -> 47983.525 | J13: Set D15 to 15:15 to run the second. It is the only place on Day 0 where one shelf is hit twice.
A14: Weddell / Filchner-Ronne | B14: westward | C14: 123 deg, ~5,800 km, ~8.0 h | D14: 47983.472 | E14: 1300 | F14: 110 | G14: =IF(E14=0,0,E14*1000/F14/3600) -> 3.2828283 | H14: =D14+G14/24 -> 47983.609 | J14: Nalani sees it as two arrivals with the same signature fifteen minutes apart — a signature no single collapse can produce, and the hardest evidence available to anyone on Day 0 that the four events are one mechanism.
A15: Amundsen (Thwaites / Pine I.) | B15: both converge | C15: 178 W / 182 E, ~8,400-8,600 km | D15: 47983.625 | E15: 0 | F15: 110 | G15: =IF(E15=0,0,E15*1000/F15/3600) -> 0 | H15: =D15+G15/24 -> 47983.625
A17: The in-embayment leg is the soft number, and it is the one to argue about.
A18: The companion analysis ran the mouth-to-front leg at deep-water speed. Most of that leg is continental shelf, where sqrt(gh) at 500 m gives about 70 m/s, not 198.
A19: Set F13 and F14 to 70 and the Ross front moves to roughly 13:54Z, the Weddell front to roughly 16:30Z. A realistic mix — deep water to the shelf break, then shelf — lands between the two.
A20: Everything on every other sheet recalculates from those cells. Nothing in this workbook is a typed-in result.
A21: T0 at Prydz Bay is fixed by the manuscript and is not an assumption. Ross, Weddell and Amundsen all are.

Sheet Transit matrix
A1: Acoustic transit, ice front to station (minutes)
A2: Shelf leg at 1,450 m/s to the shelf break, then SOFAR at 1,485 m/s. Blank where the path is blocked. Computed by tools/ims_paths.py.
A4: Station | B4: Name | C4: Kind | D4: Prydz Bay / Amery | E4: Ross | F4: Weddell / Filchner-Ronne | G4: Amundsen (Thwaites / Pine I.)
A5: HA01 | B5: Cape Leeuwin, Australia | C5: hydrophone | D5: 52.6
A6: HA02 | B6: Queen Charlotte Is., Canada | C6: T-phase | E6: 169.2 | G6: 161.6
A7: HA03 | B7: Juan Fernandez, Chile | C7: hydrophone | E7: 84.6 | G7: 55.3
A8: HA04 | B8: Crozet, France | C8: hydrophone | D8: 31.6 | F8: 70.3
A9: HA05 | B9: Guadeloupe, France | C9: T-phase
A10: HA06 | B10: Socorro Is., Mexico | C10: T-phase | E10: 134.1 | G10: 117
A11: HA07 | B11: Flores, Azores, Portugal | C11: T-phase
A12: HA08 | B12: Diego Garcia, BIOT | C12: hydrophone | F12: 123.3
A13: HA09 | B13: Tristan da Cunha, UK | C13: T-phase | F13: 52.6
A14: HA10 | B14: Ascension Is., UK | C14: hydrophone | D14: 105.8 | F14: 87.6
A15: HA11 | B15: Wake Is., USA | C15: hydrophone | E15: 122.1 | G15: 128
A17: Blank = the great-circle path is obstructed by bathymetry shallower than 1,000 m. See 'Paths & Amplitude'.

Sheet Arrivals
A1: Signal arrival at each IMS hydroacoustic station, GMT
A2: Bold = clear path. Plain = marginal. Purple = T-phase station: arrival time only, no bearing. Dash = cannot hear it. All times are 2031-05-15 GMT.
A4: Shelf | B4: Branch | C4: Wave at mouth | D4: COLLAPSE | E4: HA01 | F4: HA02 | G4: HA03 | H4: HA04 | I4: HA05 | J4: HA06 | K4: HA07 | L4: HA08 | M4: HA09 | N4: HA10 | O4: HA11 | P4: First detection | Q4: First location | R4: Blind (min)
E5: hydrophone | F5: T-phase | G5: hydrophone | H5: hydrophone | I5: T-phase | J5: T-phase | K5: T-phase | L5: hydrophone | M5: T-phase | N5: hydrophone | O5: hydrophone
A6: =Assumptions!A12 -> Prydz Bay / Amery | B6: =Assumptions!B12 -> — | C6: =Assumptions!D12 -> — | D6: =Assumptions!$H$12 -> 47983.139 | E6: =$D6+'Transit matrix'!$D$5/1440 -> 47983.175 | F6: — | G6: — | H6: =$D6+'Transit matrix'!$D$8/1440 -> 47983.161 | I6: — | J6: — | K6: — | L6: — | M6: — | N6: =$D6+'Transit matrix'!$D$14/1440 -> 47983.212 | O6: — | P6: ='Detect vs Locate'!H6 -> 47983.161 | Q6: ='Detect vs Locate'!H7 -> 47983.175 | R6: =(Q6-P6)*1440 -> 21.0096
A7: =Assumptions!A13 -> Ross | B7: =Assumptions!B13 -> eastward | C7: =Assumptions!D13 -> 47983.431 | D7: =Assumptions!$H$13 -> 47983.525 | E7: — | F7: =$D7+'Transit matrix'!$E$6/1440 -> 47983.643 | G7: =$D7+'Transit matrix'!$E$7/1440 -> 47983.584 | H7: — | I7: — | J7: =$D7+'Transit matrix'!$E$10/1440 -> 47983.618 | K7: — | L7: — | M7: — | N7: — | O7: =$D7+'Transit matrix'!$E$15/1440 -> 47983.61 | P7: ='Detect vs Locate'!H10 -> 47983.584 | Q7: ='Detect vs Locate'!H11 -> 47983.61 | R7: =(Q7-P7)*1440 -> 37.5
A8: =Assumptions!A14 -> Weddell / Filchner-Ronne | B8: =Assumptions!B14 -> westward | C8: =Assumptions!D14 -> 47983.472 | D8: =Assumptions!$H$14 -> 47983.609 | E8: — | F8: — | G8: — | H8: =$D8+'Transit matrix'!$F$8/1440 -> 47983.658 | I8: — | J8: — | K8: — | L8: =$D8+'Transit matrix'!$F$12/1440 -> 47983.695 | M8: =$D8+'Transit matrix'!$F$13/1440 -> 47983.646 | N8: =$D8+'Transit matrix'!$F$14/1440 -> 47983.67 | O8: — | P8: ='Detect vs Locate'!H15 -> 47983.646 | Q8: ='Detect vs Locate'!H16 -> 47983.658 | R8: =(Q8-P8)*1440 -> 17.7
A9: =Assumptions!A15 -> Amundsen (Thwaites / Pine I.) | B9: =Assumptions!B15 -> both converge | C9: =Assumptions!D15 -> 47983.625 | D9: =Assumptions!$H$15 -> 47983.625 | E9: — | F9: =$D9+'Transit matrix'!$G$6/1440 -> 47983.737 | G9: =$D9+'Transit matrix'!$G$7/1440 -> 47983.663 | H9: — | I9: — | J9: =$D9+'Transit matrix'!$G$10/1440 -> 47983.706 | K9: — | L9: — | M9: — | N9: — | O9: =$D9+'Transit matrix'!$G$15/1440 -> 47983.714 | P9: ='Detect vs Locate'!H20 -> 47983.663 | Q9: ='Detect vs Locate'!H21 -> 47983.706 | R9: =(Q9-P9)*1440 -> 61.7
A11: Prydz: first location 04:12Z, and lyx/ice.lyx has HA01 posting at 04:12:07Z. So the manuscript's alert instant is the instant the event becomes LOCATABLE, not the instant it is first heard — Crozet has had it since 03:51Z.
A12: Every other row on this sheet collides with the manuscript. See the Conflicts sheet.

Sheet Detect vs Locate
A1: Detection, then location — one station can never locate anything
A2: 6 of the 11 stations are hydrophone TRIADS: cross-correlating three elements gives a back-azimuth. A direction, no range.
A3: 5 are T-PHASE stations — seismometers on islands. The wave converts on the island flank, so apparent direction is where the conversion happened, not where the source is. Arrival time only, and the back-azimuth column is blank for them.
A4: 1 hydrophone = a ray. 2 hydrophones, or 1 hydrophone + 1 T-station = located. Any 3 stations = located, and the origin time falls out.
A5: Event / collapse at the front (GMT) | B5: Station name | C5: Station | D5: Kind | E5: Back-azimuth (deg) | F5: Range (km) | G5: Transit (min) | H5: Arrival (GMT) | I5: Status
A6: Prydz Bay / Amery | B6: Crozet, France | C6: HA04 | D6: hydrophone | E6: 157.5 | F6: 2806 | G6: ='Transit matrix'!$D$8 -> 31.6 | H6: =Arrivals!$H$6 -> 47983.161 | I6: DETECTED — bearing only, a ray
A7: =Assumptions!$H$12 -> 47983.139 | B7: Cape Leeuwin, Australia | C7: HA01 | D7: hydrophone | E7: 205.7 | F7: 4675 | G7: ='Transit matrix'!$D$5 -> 52.6 | H7: =Arrivals!$E$6 -> 47983.175 | I7: LOCATED — two bearings crossing, plus dT
B8: Ascension Is., UK | C8: HA10 | D8: hydrophone | E8: 155.2 | F8: 9415 | G8: ='Transit matrix'!$D$14 -> 105.8 | H8: =Arrivals!$N$6 -> 47983.212 | I8: confirms; tightens; origin time solved
A10: Ross | B10: Juan Fernandez, Chile | C10: HA03 | D10: hydrophone | E10: 201 | F10: 7517 | G10: ='Transit matrix'!$E$7 -> 84.6 | H10: =Arrivals!$G$7 -> 47983.584 | I10: DETECTED — bearing only, a ray
A11: =Assumptions!$H$13 -> 47983.525 | B11: Wake Is., USA | C11: HA11 | D11: hydrophone | E11: 183.6 | F11: 10862 | G11: ='Transit matrix'!$E$15 -> 122.1 | H11: =Arrivals!$O$7 -> 47983.61 | I11: LOCATED — two bearings crossing, plus dT
B12: Socorro Is., Mexico | C12: HA06 | D12: T-phase | E12: — | F12: 11934 | G12: ='Transit matrix'!$E$10 -> 134.1 | H12: =Arrivals!$J$7 -> 47983.618 | I12: confirms; tightens; origin time solved
B13: Queen Charlotte Is., Canada | C13: HA02 | D13: T-phase | E13: — | F13: 15057 | G13: ='Transit matrix'!$E$6 -> 169.2 | H13: =Arrivals!$F$7 -> 47983.643 | I13: confirms; tightens
A15: Weddell / Filchner-Ronne | B15: Tristan da Cunha, UK | C15: HA09 | D15: T-phase | E15: — | F15: 4669 | G15: ='Transit matrix'!$F$13 -> 52.6 | H15: =Arrivals!$M$8 -> 47983.646 | I15: DETECTED — one arrival time, nothing
A16: =Assumptions!$H$14 -> 47983.609 | B16: Crozet, France | C16: HA04 | D16: hydrophone | E16: 210.2 | F16: 6242 | G16: ='Transit matrix'!$F$8 -> 70.3 | H16: =Arrivals!$H$8 -> 47983.658 | I16: LOCATED — ray x hyperbola
B17: Ascension Is., UK | C17: HA10 | D17: hydrophone | E17: 189.8 | F17: 7780 | G17: ='Transit matrix'!$F$14 -> 87.6 | H17: =Arrivals!$N$8 -> 47983.67 | I17: confirms; tightens; origin time solved
B18: Diego Garcia, BIOT | C18: HA08 | D18: hydrophone | E18: 200.6 | F18: 10964 | G18: ='Transit matrix'!$F$12 -> 123.3 | H18: =Arrivals!$L$8 -> 47983.695 | I18: confirms; tightens
A20: Amundsen (Thwaites / Pine I.) | B20: Juan Fernandez, Chile | C20: HA03 | D20: hydrophone | E20: 193.7 | F20: 4920 | G20: ='Transit matrix'!$G$7 -> 55.3 | H20: =Arrivals!$G$9 -> 47983.663 | I20: DETECTED — bearing only, a ray
A21: =Assumptions!$H$15 -> 47983.625 | B21: Socorro Is., Mexico | C21: HA06 | D21: T-phase | E21: — | F21: 10412 | G21: ='Transit matrix'!$G$10 -> 117 | H21: =Arrivals!$J$9 -> 47983.706 | I21: LOCATED — ray x hyperbola
B22: Wake Is., USA | C22: HA11 | D22: hydrophone | E22: 164.1 | F22: 11394 | G22: ='Transit matrix'!$G$15 -> 128 | H22: =Arrivals!$O$9 -> 47983.714 | I22: confirms; tightens; origin time solved
B23: Queen Charlotte Is., Canada | C23: HA02 | D23: T-phase | E23: — | F23: 14390 | G23: ='Transit matrix'!$G$6 -> 161.6 | H23: =Arrivals!$F$9 -> 47983.737 | I23: confirms; tightens

Sheet Paths & Amplitude
A1: Path screen and received amplitude, all 44 station-event pairs
A2: Screen: great circle sampled every 10 km against Natural Earth 10 m bathymetry. CLEAR = nothing shallower than 1,000 m. MARGINAL = longest obstruction under 150 km, a ridge crest — loss, not extinction. BLOCKED = a real barrier, and the range shown is then a lower bound.
A3: Amplitude: source SEL assigned by shelf area; TL spherical to 1 km then cylindrical, plus 5e-4 dB/km absorption and 8 dB shelf-coupling excess. Noise floor over a 340 s window is 115 dB re 1 uPa^2 s.
A4: T-phase stations are seismometers and report ground velocity, not pressure. No source level may be derived from one.
A6: Event | B6: Station | C6: Name | D6: Kind | E6: Screen | F6: Range (km) | G6: Transit (min) | H6: Back-azimuth (deg) | I6: Received SEL (dB re 1 uPa^2 s) | J6: Peak pressure (Pa) | K6: Over noise (dB) | L6: Worst obstruction
A7: Prydz Bay / Amery | B7: HA01 | C7: Cape Leeuwin, Australia | D7: hydrophone | E7: CLEAR | F7: 4675 | G7: 52.6 | H7: 205.7 | I7: 156 | J7: 13.6 | K7: 41
A8: Prydz Bay / Amery | B8: HA02 | C8: Queen Charlotte Is., Canada | D8: T-phase | E8: BLOCKED | F8: 18396 | L8: 3720 km; multiple
A9: Prydz Bay / Amery | B9: HA03 | C9: Juan Fernandez, Chile | D9: hydrophone | E9: BLOCKED | F9: 9056 | L9: 6319 km; crosses the Antarctic margin
A10: Prydz Bay / Amery | B10: HA04 | C10: Crozet, France | D10: hydrophone | E10: CLEAR | F10: 2806 | G10: 31.6 | H10: 157.5 | I10: 159.1 | J10: 19.6 | K10: 44
A11: Prydz Bay / Amery | B11: HA05 | C11: Guadeloupe, France | D11: T-phase | E11: BLOCKED | F11: 13921 | L11: 5978 km; South American margin
A12: Prydz Bay / Amery | B12: HA06 | C12: Socorro Is., Mexico | D12: T-phase | E12: BLOCKED | F12: 15140 | L12: 4598 km; 140-4728 km along the Antarctic coast
A13: Prydz Bay / Amery | B13: HA07 | C13: Flores, Azores, Portugal | D13: T-phase | E13: BLOCKED | F13: 14904 | L13: 1150 km; 10528-11648 km at 7.1N 12.7W
A14: Prydz Bay / Amery | B14: HA08 | C14: Diego Garcia, BIOT | D14: hydrophone | E14: BLOCKED | F14: 6808 | L14: 429 km; KERGUELEN PLATEAU, 1348-1758 km at 53.4S 72.8E, 200-1000 m
A15: Prydz Bay / Amery | B15: HA09 | C15: Tristan da Cunha, UK | D15: T-phase | E15: BLOCKED | F15: 6433 | L15: 410 km; 680-1049 km at 66.2S 58.1E, <200 m
A16: Prydz Bay / Amery | B16: HA10 | C16: Ascension Is., UK | D16: hydrophone | E16: MARGINAL | F16: 9415 | G16: 105.8 | H16: 155.2 | I16: 150.6 | J16: 7.3 | K16: 36 | L16: 20 km sill at 33.4S 0.6W
A17: Prydz Bay / Amery | B17: HA11 | C17: Wake Is., USA | D17: hydrophone | E17: BLOCKED | F17: 13671 | L17: 1939 km; 310-1859 km at 66.3S 79.5E
A19: Ross | B19: HA01 | C19: Cape Leeuwin, Australia | D19: hydrophone | E19: BLOCKED | F19: 6307 | L19: 790 km; Balleny Is. / Macquarie Ridge
A20: Ross | B20: HA02 | C20: Queen Charlotte Is., Canada | D20: T-phase | E20: MARGINAL | F20: 15057 | G20: 169.2 | I20: 149.7 | K20: 35 | L20: 60 km sill at 17.9S 149.4W
A21: Ross | B21: HA03 | C21: Juan Fernandez, Chile | D21: hydrophone | E21: CLEAR | F21: 7517 | G21: 84.6 | H21: 201 | I21: 156.5 | J21: 14.5 | K21: 41
A22: Ross | B22: HA04 | C22: Crozet, France | D22: hydrophone | E22: BLOCKED | F22: 7063 | L22: 3637 km; crosses Antarctica
A23: Ross | B23: HA05 | C23: Guadeloupe, France | D23: T-phase | E23: BLOCKED | F23: 13385 | L23: 3489 km; South American margin
A24: Ross | B24: HA06 | C24: Socorro Is., Mexico | D24: T-phase | E24: MARGINAL | F24: 11934 | G24: 134.1 | I24: 152.3 | K24: 37 | L24: 20 km sill
A25: Ross | B25: HA07 | C25: Flores, Azores, Portugal | D25: T-phase | E25: BLOCKED | F25: 16719 | L25: 6896 km; South American and African margins
A26: Ross | B26: HA08 | C26: Diego Garcia, BIOT | D26: hydrophone | E26: BLOCKED | F26: 10640 | L26: 2498 km; crosses Antarctica
A27: Ross | B27: HA09 | C27: Tristan da Cunha, UK | D27: T-phase | E27: BLOCKED | F27: 8614 | L27: 3518 km; crosses Antarctica
A28: Ross | B28: HA10 | C28: Ascension Is., UK | D28: hydrophone | E28: BLOCKED | F28: 11820 | L28: 3178 km; crosses Antarctica
A29: Ross | B29: HA11 | C29: Wake Is., USA | D29: hydrophone | E29: CLEAR | F29: 10862 | G29: 122.1 | H29: 183.6 | I29: 153.2 | J29: 9.9 | K29: 38
A31: Weddell / Filchner-Ronne | B31: HA01 | C31: Cape Leeuwin, Australia | D31: hydrophone | E31: BLOCKED | F31: 9221 | L31: 4139 km; crosses Antarctica
A32: Weddell / Filchner-Ronne | B32: HA02 | C32: Queen Charlotte Is., Canada | D32: T-phase | E32: BLOCKED | F32: 16399 | L32: 3819 km; multiple
A33: Weddell / Filchner-Ronne | B33: HA03 | C33: Juan Fernandez, Chile | D33: hydrophone | E33: BLOCKED | F33: 5483 | L33: 1886 km; Scotia Arc / South American margin
A34: Weddell / Filchner-Ronne | B34: HA04 | C34: Crozet, France | D34: hydrophone | E34: MARGINAL | F34: 6242 | G34: 70.3 | H34: 210.2 | I34: 156.9 | J34: 15.2 | K34: 42 | L34: 10 km sill at 53.5S 45.3E
A35: Weddell / Filchner-Ronne | B35: HA05 | C35: Guadeloupe, France | D35: T-phase | E35: BLOCKED | F35: 10440 | L35: 5699 km; South American margin
A36: Weddell / Filchner-Ronne | B36: HA06 | C36: Socorro Is., Mexico | D36: T-phase | E36: BLOCKED | F36: 12127 | L36: 870 km; Scotia Arc
A37: Weddell / Filchner-Ronne | B37: HA07 | C37: Flores, Azores, Portugal | D37: T-phase | E37: BLOCKED | F37: 12838 | L37: 360 km; Mid-Atlantic Ridge crest and 55.5S 35.9W
A38: Weddell / Filchner-Ronne | B38: HA08 | C38: Diego Garcia, BIOT | D38: hydrophone | E38: MARGINAL | F38: 10964 | G38: 123.3 | H38: 200.6 | I38: 152.1 | J38: 8.8 | K38: 37 | L38: 120 km; sills at 46.8S 51.8E and 53.5S 45.0E
A39: Weddell / Filchner-Ronne | B39: HA09 | C39: Tristan da Cunha, UK | D39: T-phase | E39: CLEAR | F39: 4669 | G39: 52.6 | I39: 159 | K39: 44
A40: Weddell / Filchner-Ronne | B40: HA10 | C40: Ascension Is., UK | D40: hydrophone | E40: MARGINAL | F40: 7780 | G40: 87.6 | H40: 189.8 | I40: 155.2 | J40: 12.5 | K40: 40 | L40: 30 km sill at 56.0S 27.7W
A41: Weddell / Filchner-Ronne | B41: HA11 | C41: Wake Is., USA | D41: hydrophone | E41: BLOCKED | F41: 14426 | L41: 1130 km; 780-1899 km at 70.6S 56.6W
A43: Amundsen (Thwaites / Pine I.) | B43: HA01 | C43: Cape Leeuwin, Australia | D43: hydrophone | E43: BLOCKED | F43: 8112 | L43: 4206 km; crosses Antarctica
A44: Amundsen (Thwaites / Pine I.) | B44: HA02 | C44: Queen Charlotte Is., Canada | D44: T-phase | E44: MARGINAL | F44: 14390 | G44: 161.6 | I44: 139.2 | K44: 24 | L44: 30 km; shelf break
...

Sheet Conflicts with ice.lyx
A1: Where these timings collide with the manuscript
A2: CLAUDE.md: the manuscript is ground truth and a conflict means the outline is stale. Reported, not reconciled. Nothing here has been applied.
A4: # | B4: What | C4: ice.lyx says | D4: This workbook says | E4: Size of the move | F4: Comment
A5: 1 | B5: Order of collapse | C5: Prydz, Weddell, Amundsen, then Ross (Ross has no origin time anywhere) | D5: Prydz, Ross, Weddell, Amundsen | E5: Ross moves from 4th to 2nd | F5: The circumpolar geometry puts Ross 107 deg east of Prydz and the Weddell 123 deg west, so Ross is rung down first. This is the load-bearing conflict; everything else follows from it.
A6: 2 | B6: Weddell collapse | C6: 10:05:00Z, stated in Edgar's block | D6: 13:09Z on the deep-water leg; ~16:30Z at shelf speed | E6: +3 h 04 m or more | F6: Edgar's Crozet notice moves with it.
A7: 3 | B7: Crozet posts the Weddell | C7: 10:51Z | D7: 14:19Z | E7: +3 h 28 m | F7: And if the Prydz arrival kills Crozet, Crozet never posts it at all: first location falls to Ascension at 14:36Z.
A8: 4 | B8: Amundsen collapse | C8: 14:50Z, stated in Edgar's block | D8: 15:00Z (first branch) or 15:15Z (second) | E8: +10 to +25 m | F8: Small. The Amundsen sits nearly antipodal to Prydz and both branches converge there, which is why it is last either way.
A9: 5 | B9: HA03 posts the Amundsen | C9: 15:44Z | D9: 15:55Z | E9: +11 m | F9: Daniel's beepers move from just after 11:45 to just before 12:00 his time.
A10: 6 | B10: PTWC Ross statement | C10: 16:22Z, sea level at Scott Base and three Ross DARTs, no seismic origin | D10: Ross collapses 11:35Z and is acoustically located 13:37Z | E10: PTWC is 2 h 45 m late | F10: Under the new order the Ross event is located BEFORE PTWC reports water moving, which inverts the beat. Either PTWC moves earlier or the Ross front is pushed later by the shelf-speed correction.
A11: 7 | B11: HA01 back-azimuth | C11: 189 deg | D11: 206 deg | E11: 17 deg | F11: Unchanged from Hydroacoustics.md section 4. 189 points at Wilkes Land, not Prydz Bay.
A12: 8 | B12: HA04 back-azimuth to the Weddell | C12: 209 deg | D12: 210.2 deg | E12: 1.2 deg | F12: Correct as written. Do not touch it.
A14: The one to decide first is #1. If Ross is second, S2's whole morning reorders.
